<!DOCTYPE html>
<html lang="fr">
<head>
    <meta charset="UTF-8">
    <meta name="viewport" content="width=device-width, initial-scale=1.0">
    <link rel="stylesheet" href="/src/assets/css/main.css">
    <script src="/src/assets/js/scripts.js"></script>
    <script src="/src/assets/js/knowledge/data-analytics/mathematics/probabilities/probability-distributions/continuous-probability-distributions/normal-distribution.js"></script>
    <link rel="stylesheet" href="/src/assets/lib/katex/katex.css">
    <script src="/src/assets/lib/katex/katex.js"></script>
    <title>Votre Nom - Data Analyst</title>
</head>
<body>
    <nav class="header-menu">
        <ul class="header-menu__list">
            <li class="header-menu__item">
                <a class="header-menu__link" href="/src/index.html">Accueil</a>
            </li>
            <li class="header-menu__item">
                <a class="header-menu__link" href="/src/about.html">À Propos</a>
            </li>
            <li class="header-menu__item">
                <a class="header-menu__link" href="/src/knowledge/index.html">Connaissances</a>
            </li>
            <li class="header-menu__item">
                <a class="header-menu__link" href="/src/projects/index.html">Projets Réalisés</a>
            </li>
            <li class="header-menu__item">
                <a class="header-menu__link" href="/src/contact.html">Contact</a>
            </li>
        </ul>
    </nav>
    
    <div class="knowledge-container">
        
        <iframe class="knowledge-iframe" src="/src/knowledge/utils/knowledge-nav.html"></iframe>
    
        <main class="knowledge-content">
            <section id="python-asyncio__introduction">
                <h1>Exceptions</h1>
                <p>
                    La gestion des exceptions dans asyncio est similaire à celle de la programmation synchrone en Python, mais avec quelques spécificités dues à la nature asynchrone de l'exécution. Les exceptions dans les coroutines, les tâches, et pendant l'interaction avec la boucle d'événements doivent être soigneusement gérées pour assurer la robustesse de l'application.
                </p>
            </section>
            <section id="python-asyncio__keys-concepts">
                <h2>Gestion des Exceptions dans les Coroutines</h2>
                <p>
                    Les exceptions levées dans une coroutine peuvent être capturées et gérées à l'aide de blocs try/except.
                </p>
                <pre><code>
import asyncio

async def might_fail():
    if random.choice([True, False]):
        raise Exception("Erreur aléatoire")

async def main():
    try:
        await might_fail()
    except Exception as e:
        print(f"Une exception a été attrapée: {e}")

asyncio.run(main())                                                                         
                </code></pre>
                <p>
                    Dans cet exemple, la coroutine might_fail peut lever une exception. La fonction main capture cette exception et affiche un message.
                </p>
                <h2>Gestion des Exceptions dans les Tâches</h2>
                <p>
                    Lorsqu'une tâche lève une exception, elle est stockée jusqu'à ce que la tâche soit attendue avec await. Si l'exception n'est pas récupérée, elle sera propagée à ce moment.
                </p>
                <pre><code>
async def task():
    raise Exception("Erreur dans la tâche")

async def main():
    t = asyncio.create_task(task())

    try:
        await t
    except Exception as e:
        print(f"Exception depuis la tâche: {e}")

asyncio.run(main())
                </code></pre>
                <p>
                    Dans cet exemple, l'exception levée dans task() est capturée lorsque la tâche t est attendue dans main().
                </p>
                <h2>Annulation de Tâche et CancelledError</h2>
                <p>
                    Une tâche peut être annulée, ce qui lève une asyncio.CancelledError dans la tâche. Il est important de gérer cette exception pour nettoyer correctement les ressources.
                </p>
                <pre><code>
async def cancellable_task():
    try:
        await asyncio.sleep(5)
    except asyncio.CancelledError:
        print("Tâche annulée")
        raise

async def main():
    t = asyncio.create_task(cancellable_task())

    await asyncio.sleep(1)
    t.cancel()

    try:
        await t
    except asyncio.CancelledError:
        print("Exception CancelledError capturée dans main")

asyncio.run(main())                                          
                </code></pre>
                <p>
                    Ici, la tâche est annulée depuis main(), ce qui provoque une CancelledError dans cancellable_task.
                </p>
                <h2>Exceptions lors de l'Exécution de Plusieurs Tâches</h2>
                <p>
                    Lors de l'exécution de plusieurs tâches avec asyncio.gather(), une exception dans l'une des tâches entraînera l'annulation des autres.
                </p>
                <pre><code>
async def fail():
    await asyncio.sleep(1)
    raise Exception("Tâche en échec")

async def succeed():
    await asyncio.sleep(2)
    return "Succès"

async def main():
    try:
        results = await asyncio.gather(fail(), succeed())
    except Exception as e:
        print(f"Exception attrapée dans main: {e}")

asyncio.run(main())
                </code></pre>
                <p>
                    Dans cet exemple, asyncio.gather() attend que toutes les tâches soient complétées. Si une des tâches échoue, une exception est levée et capturée dans main.
                </p>
            </section>
        </main>
    </div>

    <footer>
        <p><a href="/src/credits.html">Crédits</a> | <a href="/src/contact.html">Contact</a> | <a href="/src/curriculum-vitae.html">Curriculum vitae</a></p>
    </footer>
    
</body>
</html>